  <?xml version="1.0" ?>
  <robot name="3R_planar_manipulator">

    <material name="blue">
      <color rgba="0 0 0.8 1"/>
    </material>
    
    <material name="red">
      <color rgba="0.8 0 0 1"/>
    </material>

    <material name="green">
      <color rgba="0 0.8 0 1"/>
    </material>

  <link name="base_link"/>

  <joint name="joint_1" type="revolute">
      <parent link="base_link"/>
      <child link="link_1"/>
      <origin xyz="0 0 0" rpy="0 1.57 0" />
      <axis xyz="0 -1 0"/>
      <limit effort="10" lower="0.0" upper="3.14" velocity="0.0005"/>
  </joint>

  <link name="link_1">  
      <visual>
          <origin xyz="0 0 0.5" rpy="0 0 0" />
            <geometry>
              <cylinder radius="0.1" length="1.0" />
            </geometry>
          <material name="red"/>
      </visual>
      <inertial>
        <origin xyz="0 0 0.5"/>
        <mass value="1.0"/>
        <inertia ixx="0.05" ixy="0.0" ixz="0.0" iyy="0.05" iyz="0.0" izz="0.025"/>
      </inertial>
  </link>

  <joint name="joint_2" type="revolute">
      <parent link="link_1"/>
      <child link="link_2"/>
      <origin xyz="0 0 1" rpy="0 0 0" />
      <axis xyz="0 -1 0"/>
      <limit effort="10" lower="-3.14" upper="3.14" velocity="0.0005"/>
  </joint>

  <link name="link_2">
      <visual>
          <origin xyz="0 0 0.5" rpy="0 0 0" />
          <geometry>
          <cylinder radius="0.1" length="1.0" />
          </geometry>
          <material name="green"/>
      </visual>
      <inertial>
        <origin xyz="0 0 0.5"/>
        <mass value="1.0"/>
        <inertia ixx="0.05" ixy="0.0" ixz="0.0" iyy="0.05" iyz="0.0" izz="0.025"/>
      </inertial>    
  </link>

  <joint name="joint_3" type="revolute">
      <parent link="link_2"/>
      <child link="link_3"/>
      <origin xyz="0 0 1" rpy="0 0 0" />
      <axis xyz="0 -1 0"/>
      <limit effort="10" lower="-3.14" upper="3.14" velocity="0.0005"/>
  </joint>

  <link name="link_3">
      <visual>
          <origin xyz="0 0 0.5" rpy="0 0 0" />
            <geometry>
              <cylinder radius="0.1" length="1.0" />
            </geometry>
          <material name="blue"/>
      </visual>
      <inertial>
        <origin xyz="0 0 0.5"/>
        <mass value="1.0"/>
        <inertia ixx="0.05" ixy="0.0" ixz="0.0" iyy="0.05" iyz="0.0" izz="0.025"/>
      </inertial>
  </link>

  <joint name="end_effector" type="fixed">
      <parent link="link_3"/>
      <child link="gripper"/>
      <origin xyz="0 0 1" rpy="0 0 0" />
      <axis xyz="0 0 1"/>
  </joint>

  <link name="gripper">
      <visual>
          <origin xyz="0 0 0.05" rpy="0 0 0" />
            <geometry>
              <sphere radius="0.1" />
            </geometry>
          <material name="red"/>
      </visual>
  </link>

  </robot>
